Workbook
Name Area_Desc.: 'Risk Assessment || Step 1'!$D$6
Name Area_Equipment: 'Risk Assessment || Step 1'!$C$6

Sheet Sheet1

Sheet Sikeston Compliance Items
A1: Safety & Health Standards | B1: REG | C1: U | D1: UA | E1: Affected Department | F1: Compliant | G1: Date Reviewed
E2: Co-Workers | F2: Y / N
A3: Unilever Framework Standards
A4: 020100 – Occupational health and safety policy VT FWS 01 | E4: Supply Leader, SHE, Everyone At Site | G4: 42741
A5: All Unilever organizations must prepare, document and update an appropriate occupational health and safety policy, which is consistent with the Unilever occupational health and safety policy. It must be signed by the current most senior line person on site and communicated to the whole organization. It must be reviewed annually. | F5: Y
A6: 020200 - Occupational health and safety risk assessment VT FWS 02 | E6: SHE, Site Leadership, Safety Committees | F6: Y | G6: 41848
A7: Each organization must identify the hazards arising from its operations, activities and services and determine those that may impact on occupational health and safety. Risk assessments relating to significant occupational health & safety risks must be documented and then kept under periodic review.
A8: 020300 - Legal and other requirements VT FWS 03 | E8: SHE, Site Leadership | F8: y | G8: 41849
A9: Each site must comply with all local health and safety legislation and with any Unilever or company standards. Compliance will be with whichever is the stricter of these and it must be documented.
A10: 020400 - Objectives and targets VT FWS 04 | E10: Supply Leader, SHE, SHE Council | F10: Y | G10: 41850
A11: Each organization must establish, document and maintain a set of specific occupational health and safety objectives and targets, relevant to its current significant occupational health and safety risks and consistent with its occupational health & safety policy
A12: 020500 - Occupational health and safety management program VT FWS 05 | E12: SHE, SHE Council, Safety Committees | F12: Y | G12: 41854
A13: Each organization must establish and maintain a written management program (improvement plan) for achieving its objectives and targets. The means, responsibilities and time-scales for achieving the organization’s objectives and targets must be clearly defined and adequate resources provided. The management program must be reviewed at regular and planned intervals and revised as appropriate to reflect changing circumstances.
A14: 020600 - Structure and responsibility VT FWS 06 | E14: SHE, Site Leadership, SHE Council, Safety Committees | F14: Y | G14: 42196
A15: Each Company must nominate a senior line manager responsible for occupational health and safety within the company operations and each site must nominate a senior manager on site with similar responsibilities. In addition, each site must be supported by a qualified safety adviser and occupational health adviser.
A16: 020700 - Training, awareness and competence VT FWS 07 | E16: SHEQ, SHE, Site Leadership | F16: Y | G16: 41945
A17: All employees must be given appropriate training covering safety induction, specific training (e.g. fork lift truck drivers), and safety awareness training. Such training must be regularly reviewed and updated.
A18: 020800 – Communication VT FWS 08 | E18: SHE, Site Leadership, SHE Council, Safety Committees | F18: Y | G18: 42297
A19: Each organization must periodically provide occupational health and safety information, as requested by Unilever, by its parent organization e.g. Business Group, or where legally required to do so e.g. by an external authority. There must be a system for receiving, documenting and responding to relevant communication from external interested parties.
A20: 020900 – Documentation VT FWS 09 | E20: SHE, Site Leadership | F20: Y | G20: 42297
A21: Each organization must establish and maintain an information system, in paper or electronic form, which:
A22: · Describes the core elements of the management system and their interaction,
A23: · provides direction to related documentation.
A24: 021000 - Document and data control VT FWS 10 | E24: SHE, Site Leadership | F24: Y | G24: 41846
A25: Each organization must establish and maintain systems for the management of all statutory and other critical documents and data relating to its occupational health and safety management system.
A26: 021100 – Operational control VT FWS 11 | E26: SHE, Site Leadership | F26: Y | G26: 41827
A27: Having established its significant occupational health and safety risks, each organization must identify those operations and activities where control measures need to be applied and implement methods of control.
A28: 021200 - Emergency preparedness and response VT FWS 12 | E28: SHE, Site Leadership, HRBP | F28: Y | G28: 41842
A29: Each organization must periodically identify and evaluate the hazards arising from its operations, activities and services to determine the potential for serious incidents or emergency situations and then establish and document comprehensive emergency plans to prevent or at least mitigate the likely consequences associated with each potentially serious incident or emergency situation. Where practicable (possible), each organization must periodically7 practice their emergency plans.
A30: 021300 – Performance measurement and monitoring VT FWS 13 | E30: SHE, Site Leadership | F30: Y | G30: 41843
A31: Each organization must establish and maintain systems to monitor and measure its occupational health and safety performance on a regular basis.
A32: 021400 - Accidents, incidents, non-conformances and corrective and preventive action | E32: SHE, Site Leadership, SHE Council, Everyone at the site | F32: Y | G32: 41857
A33: VT FWS 14
A34: Each organization must establish and maintain systems for
A35: · the reporting and investigation of:
A36: · occupational injuries,
A37: · occupational illnesses ,
A38: · non conformances
A39: · the reporting of serious accidents and incidents to Unilever,
A40: · taking action to mitigate any consequences arising from such events,
...

Sheet Hammond Compliance Items 
A2: Factory Safety Compliance Calender
A3: Category | B3: Description | D3: Fact | E3: Regulation (Standards - 29 CFR) | F3: Category | G3: Frequency | H3: R | I3: A | J3: C | K3: I
A4: Reactive | B4: Safety Policy review | D4: UL Requirment | E4: - | F4: Document | G4: Yearly | H4: SHE - Mgr | I4: Fact Dir | J4: Corp SHE | K4: All Emp, Visitors, Contractors
B5: Compliance with Legal requirements | D5: UL Requirment | E5: - | F5: Document | G5: Various | H5: SHE - Mgr | I5: Fact Dir | J5: Corp SHE | K5: All Emp, Visitors, Contractors
B6: PITs (Forklifts, Scissor Lifts, Aerial Boom Lifts) | D6: Legal Requirment | E6: 1910.178 | F6: Inspections | G6: Weekly | H6: Operators | I6: Oper Mgr | J6: SHE Mgr | K6: All Emp, Visitors, Contractors
B7: Battery Operated Pallet Trucks (Worksaver) | D7: Legal Requirment | E7: 1910.178 | F7: Inspections | G7: Weekly | H7: Operators | I7: Oper Mgr | J7: SHE Mgr | K7: All Emp, Visitors, Contractors
B8: Alarms Connected to Sprinkler Systems | D8: Legal Requirment | E8: 1910.164 | F8: Inspections | G8: Quarterly | H8: Operators | I8: Oper Mgr | J8: SHE Mgr | K8: All Emp, Visitors, Contractors
B9: Power Tools, Compressed Air for Cleaning | D9: Legal Requirment | E9: 1910.242(b) | F9: Inspections | G9: Quarterly | H9: Operators | I9: Oper Mgr | J9: SHE Mgr | K9: All Emp, Visitors, Contractors
B10: Docks | D10: Legal Requirment | E10: 1910.26 | F10: Inspections | G10: Monthly | H10: Operators | I10: Oper Mgr | J10: SHE Mgr | K10: All Emp, Visitors, Contractors
B11: E- Lights | D11: Legal Requirment | E11: 1910.37(a)(4) | F11: Inspections | G11: Monthly | H11: Operators | I11: Oper Mgr | J11: SHE Mgr | K11: All Emp, Visitors, Contractors
B12: Eye Wash Stations | D12: Legal Requirment | E12: 1910.151 | F12: Inspections | G12: Monthly | H12: Operators | I12: Oper Mgr | J12: SHE Mgr | K12: All Emp, Visitors, Contractors
B13: Fire Extinguishers | D13: Legal Requirment | E13: 1910.16, 1910.157 | F13: Inspections | G13: Monthly | H13: Operators | I13: Oper Mgr | J13: SHE Mgr | K13: All Emp, Visitors, Contractors
B14: Hoist Inspections (I Beams, NBS, Certified Anchor Points) | D14: Legal Requirment | E14: 1910.179 | F14: Inspections | G14: Monthly | H14: Operators | I14: Oper Mgr | J14: SHE Mgr | K14: All Emp, Visitors, Contractors
B15: Ladders | D15: Legal Requirment | E15: 1910.23, 1910.25, SHE Standard | F15: Inspections | G15: Annually | H15: Operators | I15: Oper Mgr | J15: SHE Mgr | K15: All Emp, Visitors, Contractors
B16: Spill Kits, First Aid Kits, AEDs | D16: Legal Requirment | E16: 1910.120, 1910.151(b) | F16: Inspections | G16: Monthly | H16: Operators | I16: Oper Mgr | J16: SHE Mgr | K16: All Emp, Visitors, Contractors
B17: Electrical Gloves (External) | D17: Legal Requirment | E17: 1910.137 | F17: Inspections | G17: Biannually | H17: Operators | I17: Oper Mgr | J17: SHE Mgr | K17: All Emp, Visitors, Contractors
B18: Gas Monitors (for confined spaces)- External | D18: Legal Requirment | E18: 1910.146(d)(4) | F18: Inspections | G18: Annually | H18: Operators | I18: Oper Mgr | J18: SHE Mgr | K18: All Emp, Visitors, Contractors
B19: Fall Protection (Harness, Anchor Strap, Retractable, Retrieval Device)- External | D19: Legal Requirment | E19: 1910.140(c)(17), 1910.146(k) | F19: Inspections | G19: Annually | H19: Operators | I19: Oper Mgr | J19: SHE Mgr | K19: All Emp, Visitors, Contractors
B20: Hoist Testing (External) | D20: Legal Requirment | E20: 1910.179 | F20: Inspections | G20: Annually | H20: Operators | I20: Oper Mgr | J20: SHE Mgr | K20: All Emp, Visitors, Contractors
B21: Emergency Alarm Testing | D21: Legal Requirment | E21: 1910.165 | F21: Inspections | G21: Annually | H21: Operators | I21: Oper Mgr | J21: SHE Mgr | K21: All Emp, Visitors, Contractors
B22: Fire Fighting System (Sprinklers Main Drain Flow Test, Extinguishers, Hose Reels, Alarms to Smoke/Heat Detectors, FM-200, etc.) | D22: Legal Requirment | E22: 1910.159, 1910.164, 1910.160, 1910.157 | F22: Inspections | G22: Annually | H22: Operators | I22: Oper Mgr | J22: SHE Mgr | K22: All Emp, Visitors, Contractors
B23: Diesel Pump Annual Flow Test- External | D23: Legal Requirment | E23: NFPA 25 | F23: Inspections | G23: Annually | H23: Operators | I23: Oper Mgr | J23: SHE Mgr | K23: All Emp, Visitors, Contractors
B24: Critical Pressure Equipment (CPE) and Safety Relief Valves (SRV) | D24: Legal Requirment | E24: ASME Section VIII, ASME BPV Code | F24: Inspections | G24: Annually | H24: Operators | I24: Oper Mgr | J24: SHE Mgr | K24: All Emp, Visitors, Contractors
B25: Elevator Certificates (External) | D25: Legal Requirment | E25: 1917.116 | F25: Inspections | G25: Annually | H25: Operators | I25: Oper Mgr | J25: SHE Mgr | K25: All Emp, Visitors, Contractors
B26: Dock Levelers | D26: Legal Requirment | E26: ANSI standard MH30.1-2000 | F26: Inspections | G26: Annually | H26: Operators | I26: Oper Mgr | J26: SHE Mgr | K26: All Emp, Visitors, Contractors
B27: Outdoor Access Ladders?? | D27: Legal Requirment | E27: 1910.28(b)(10) | F27: Inspections | G27: Annually | H27: Operators | I27: Oper Mgr | J27: SHE Mgr | K27: All Emp, Visitors, Contractors
B28: Audiogram Testing | D28: Legal Requirment | E28: 1910.95 | F28: Inspections | G28: Annually | H28: Operators | I28: Oper Mgr | J28: SHE Mgr | K28: All Emp, Visitors, Contractors
B29: Thermography (Infrared Electrical Inspections) | D29: Legal Requirment | E29: NFPA 70B 11.17.5 | F29: Inspections | G29: Annually | H29: Operators | I29: Oper Mgr | J29: SHE Mgr | K29: All Emp, Visitors, Contractors
B30: OSHA 300 Log, OSHA Poster | D30: Legal Requirment | E30: 1903, 1904 | F30: Communications | G30: Annually | H30: Operators | I30: Oper Mgr | J30: SHE Mgr | K30: All Emp, Visitors, Contractors
B31: Written Emergency Response Plan | D31: Legal Requirment | E31: 1910.120 (q)(1) & (2), 1910.38 | F31: Document | G31: Annually | H31: Operators | I31: Oper Mgr | J31: SHE Mgr | K31: All Emp, Visitors, Contractors
B32: Active Aggressor | D32: Legal Requirment | E32: 1910.38 | F32: Drills | G32: Every Two Years | H32: Operators | I32: Oper Mgr | J32: SHE Mgr | K32: All Emp, Visitors, Contractors
B33: External Evac (Fire, Major Spill/Release) | D33: Legal Requirment | E33: 1910.38 | F33: Drills | G33: Annually | H33: Operators | I33: Oper Mgr | J33: SHE Mgr | K33: All Emp, Visitors, Contractors
B34: Fire Department Walk Thorough (Include Rescue) | D34: Legal Requirment | E34: 1910.38 | F34: Drills | G34: Annually | H34: Operators | I34: Oper Mgr | J34: SHE Mgr | K34: All Emp, Visitors, Contractors
B35: Police Department Walk Thorough (Include Active shooter Training) | D35: Legal Requirment | E35: 1910.38 | F35: Drills | G35: Annually | H35: Operators | I35: Oper Mgr | J35: SHE Mgr | K35: All Emp, Visitors, Contractors
B36: Shelter in Place (Inclemete Weather) | D36: Legal Requirment | E36: 1910.38 | F36: Drills | G36: Annually | H36: Operators | I36: Oper Mgr | J36: SHE Mgr | K36: All Emp, Visitors, Contractors
B37: Access to Medical Records | D37: Legal Requirment | E37: 1910.102 | F37: Trainings | G37: Annually | H37: Operators | I37: Oper Mgr | J37: SHE Mgr | K37: All Emp, Visitors, Contractors
B38: Electrical Safety | D38: Legal Requirment | E38: 1910.331 | F38: Trainings | G38: Annually | H38: Operators | I38: Oper Mgr | J38: SHE Mgr | K38: All Emp, Visitors, Contractors
B39: Emergency Action Plan | D39: Legal Requirment | E39: 1910.38, 1910.165 | F39: Trainings | G39: Annually | H39: Operators | I39: Oper Mgr | J39: SHE Mgr | K39: All Emp, Visitors, Contractors
B40: Hazardous Energy Control | D40: Legal Requirment | E40: 1910.147 | F40: Trainings | G40: Annually | H40: Operators | I40: Oper Mgr | J40: SHE Mgr | K40: All Emp, Visitors, Contractors
B41: Hazcom & Hazardous Material (SDS Access, Secondary Labeling, HFR Meaning) | D41: Legal Requirment | E41: 1910.12 | F41: Trainings | G41: Annually | H41: Operators | I41: Oper Mgr | J41: SHE Mgr | K41: All Emp, Visitors, Contractors
...

Sheet |NOTES|
A2: - | B2: **Important** do not download or save this workbook to another location. If you have to download a copy, make sure any updates you make are reflected in this LIVE working copy on Sharepoint.
A4: - | B4: Most of this workbook is free text input, except where noted, as below:
C5: Fields with this color marking above are drop down fields. Please select a value from the drop down box, instead of typing.
C6: Fields with this color marking above are auto-calculated fields. These will auto-populate values based on data entered in other cells. These fields are locked & non-editable.
A8: - | B8: Use "Step 1 || What to look for" sheet to determine non-compliance items & what control improvments should look like.
A9: - | B9: Use "Risk Matrix" sheet to determine probability & severity for Steps 3/4 of assessment.

Sheet |EXAMPLES|
A23: Risk Assessment || Step 3
A56: Risk Assessment || Step 4

Sheet |Drop Down Control|
A1: Drop Down Control List for "Non-Compliance Category" Field | C1: Drop Down Control List for "Area" Field | E1: Drop Down Control List for "Machine" Field
A2: Accident/Incident Reporting | C2: Air Compressor Room | E2: Carton Closer
A3: Walking Working Surfaces | C3: Battery Charging Areas | E3: Depositer
A4: Emergency Response/Fire Protection | C4: Battery Charging Areas - 11 | E4: Freezer 1
A5: Hazardous Material | C5: Battery Charging Areas - 36 | E5: HSW
A6: PPE | C6: Boiler Room | E6: Harvester, Mould Table & Paper Magazine
A7: Material Handling /Warehouse Safety | C7: Minto Building | E7: Robotic Case Packer
A8: Machine Guarding, LOTO | C8: CANI Cleaning Chemicals Storage Area | E8: Stick Inserter
A9: Health Physical | C9: Compounding | E9: Suck Out, Taper
A10: Health Biological | C10: Compounding Electrical Room | E10: Carton Former
A11: Health Chemical | C11: Fragrance | E11: Filler 1
A12: Hazardous Building Material | C12: Global Containment | E12: Filler 2
... A19: Risk Management/Risk Assessments | C19: Stick 1 | E19: Diverter
C20: Stick 2 | E20: Fruit Feeder
C21: Spiral | E21: PINT Line
C22: Bar Line 2 | E22: GMF
C23: Bar Line 4 | E23: Case Packer
C24: Mix Room 1 Batching | E24: Choc Melt Tanks
C25: Mix Room 2 Batching | E25: Dipping System
C26: Ammonia Refrigeration Plant | E26: Extruders
C27: Aging Tank Farm 1 | E27: Label Applicator
C28: Aging Tank Farm 2 | E28: Nose Dispenser
C29: Ambient Room Tanks | E29: SAM
C30: Cream & Rework Tanks | E30: Stick Inserters
C31: De-Packing & Compactor Area | E31: Rotory Freezer
... C39: Engineering & Maintenace | E39: Mix 2 Batching Tank
C40: Maintenance Work Shop 1
C41: Maintenace Work Shop 2

Sheet Risk Assessment || Step 1
G1: Completed by: | H1: SHE Lead - Madhusanka Rathnayake
G2: Date of Assessment: | H2: 45822
A3: Step 1: Compliance Risk Assessment | J3: Action Planning & Status
O4: Do not paste over
C5: Drop-down Field | E5: Drop-down Field | H5: Drop-down Field | N5: Drop-down Field | O5: Auto-Calc Field
C6: Area | D6: Description of Area | E6: Non-Compliance Category | F6: Non-Compliance Description | G6: Standard Reference | H6: Status Ranking | J6: Description of recommended control improvements | K6: Owner: | L6: Target Completion Date | M6: Completion Date | N6: Capex Required? | O6: Status | P6: Notes:
C7: Minto Factory | D7: Occupancy Certificate | E7: Building Occupancy | F7: No Records of Municipal Council approved OC | G7: NSW WHS | H7: Unsafe Condition/Documentation - Low Risk | J7: Obtain OC | K7: Kapildev Sharma | L7: 45899 | N7: No
C8: Minto Factory | D8: Pressure Vessel | E8: Process Safety | F8: Pressure vessel due in several areas | G8: NSW WHS | H8: Unsafe Condition - High Risk | J8: Complete PV Inspections | K8: Lorna/Ahmed | L8: 45868
C9: Upper Stores | D9: High Risk Licence (Forklift) | E9: Material Handling /Warehouse Safety | F9: Re-newal of FLT liceses are in progress | G9: NSW WHS | H9: Unsafe Condition/Documentation - Low Risk | J9: Complete all FLT trainings | K9: Dianne/Lea | L9: 45899
C10: Minto Factory | D10: Fall Arrest Equipment | E10: High Risk Activities (PTW) | F10: Inspection Due | G10: NSW WHS | H10: Unsafe Condition - High Risk | J10: Complete all Inspection and tagout all un unsables | K10: Burhan/Wayne | L10: 45868
C11: Minto Factory | D11: Slings and Chains | E11: High Risk Activities (PTW) | F11: Inspection Due | H11: Unsafe Condition - High Risk | J11: Complete all Inspection and tagout all un unsables | K11: Burhan/Wayne | L11: 45868
C12: Minto Factory | D12: Hoist | E12: High Risk Activities (PTW) | F12: Inspection Due | H12: Unsafe Condition - High Risk | J12: Complete all Inspection and tagout all un unsables | K12: Burhan/Wayne | L12: 45868
C13: Minto Factory | D13: Warehourse Racking | E13: Material Handling /Warehouse Safety | F13: Report Pending | H13: Unsafe Condition - Medium Risk | J13: Wating for Report | K13: Dianne/Lea
C14: Minto Factory | D14: RCD | E14: Electrical Safety | F14: Inspection Due | H14: Unsafe Condition - High Risk | J14: Complete Test | K14: Anees
C15: Minto Factory | D15: Electrical Test and Tag | E15: Electrical Safety | F15: Inspection Due | H15: Unsafe Condition - High Risk | J15: Complete Test | K15: Anees
C16: Minto Factory | D16: First Aid - Eye wash station and Safety Shower | E16: Emergency Response/Fire Protection | H16: Unsafe Condition - High Risk | J16: Complete Inspection | K16: Burhan/Wayne | L16: 45838
C17: Minto Factory | D17: Emergency Planning | E17: Emergency Response/Fire Protection | F17: Revision In Progress
C18: Minto Factory | D18: Confined Spaces | E18: High Risk Activities (PTW) | F18: Need to update register and stickering | H18: Unsafe Condition - High Risk | J18: Identify all CS in register and provide all visual signages in relevent areas | K18: Wayne | L18: 45899
C19: Minto Factory | D19: Hazardous Chemicals | E19: Health Chemical | F19: need to update register and overall chemical handling | H19: Unsafe Condition - High Risk | J19: Update Chemical Register and Chemical handling, Signages etc | K19: Farshid | L19: 45868
C20: Minto Factory | D20: Hazardous Manual Tasks | E20: Risk Management/Risk Assessments | F20: Need to update task register | H20: Unsafe Condition - Medium Risk | J20: Complete UMS Step3 | K20: Madhusanka | L20: Q2-2026
C21: Minto Factory | D21: Falls | E21: High Risk Activities (PTW)
C22: Minto Factory | D22: MHE equipment | E22: Material Handling /Warehouse Safety | F22: Not all MHE inlcuded in Register/ Test and tagging due | G22: Unilever MMHE Standard and NSW WHS | H22: Unsafe Condition - High Risk | J22: Need to finalize MMHE Survey and Update Register | K22: Dianne | L22: 45868
C23: Minto Factory | D23: Pressure Relief Valves | E23: Process Safety | F23: Inspection Due | H23: Unsafe Condition - High Risk | J23: Need to inlcude PRVs related to steam distribution also to the regsiter | K23: Ahmed | L23: 45868
C24: Minto Factory | D24: Ladders | E24: High Risk Activities (PTW) | F24: Inspection Due | H24: Unsafe Condition - High Risk | J24: Get inspection for latters done | K24: Burhan/Wayne | L24: 45838

Sheet Step 1 || What to look for
B2: Topic | C2: Item | D2: What to look for…
B3: Accident/Incident Reporting | C3: Accident/Incident Reporting | D3: Process in place to report
B4: Walking Working Surfaces | C4: Ladders | D4: Inspected, good condition
C5: Stairways | D5: Handrails present, clear of trip hazards
C6: Fall Protection Systems | D6: Inspected, good condition
C7: Falling Object Protection | D7: Guarding to prevent falling objects
C8: Slip/trip/fall | D8: Area is clear of hazards
C9: Pedestrian Safety | D9: Paths, barriers
B10: Emergency Response/Fire Protection | C10: Exits & pathways | D10: 3ft egress, clear doors
C11: Fire Extinguishers | D11: Inspected and tested. Not blocked
C12: Fire detection systems | D12: Inspected
C13: Alarms | D13: Inspected
C14: Fire Hoses | D14: Inspected
C15: Emergency Lighting | D15: Inspected & tested monthly, sufficient lighting for occupants to exit safely
C16: Eye Wash /Showers | D16: Inspected, available where there is chemical handling
C17: First Aid/AEDs | D17: Readily available and inspected, first aider present, AED available in 3 mins,
C18: Emergency Signage | D18: Clear and mark location of emergency routes, first aid kits, eyewash/showers etc…
B19: Hazardous Material | C19: Compressed Gas | D19: Storage, Handling, Labels
C20: Flammable Liquids | D20: Storage, Handling, Dispensing, Area Classification
C21: Hazardous Waste | D21: Process for disposal
C22: Hazardous Materials | D22: SDS Sheets, emergency procedure, training, lableling
B23: PPE | C23: PPE | D23: Hazard Assessment Survey completed, PPE required is defined
C24: Fall Protection | D24: Defined if required, inspected, training for use
B25: Material Handling /Warehouse Safety | C25: Slings | D25: Inspections, working order, meet manufacturers requirements
C26: Hoists | D26: Inspections, working order, meet manufacturers requirements
C27: Cranes | D27: Inspections, working order, meet manufacturers requirements
C28: Powered Industrial Trucks | D28: Inspections, working order, meet manufacturers requirements, written program present
C29: Truck Loading and Unloading | D29: Process to prevent truck from pulling out
B30: Machine Guarding, LOTO | C30: Machine Guarding | D30: Meet UL requirements ( prevent access)
C31: Emergency Stops | D31: Present, tested
C32: Handheld tools | D32: Inspection to manfactures spec.
C33: LOTO | D33: Energy control procedure, training, review of procedures
C34: ACM | D34: Procedure, training to procedure
B35: Health Physical | C35: Ergonomics | D35: Lifting, lowering, pushing, pulling, shift work, tools use
C36: Heat Stress/ Cold Stress | D36: Temperature/Humdity
C37: Noise/ Vibration | D37: Hearing conservation program
C38: Radiation | D38: Expsoure assessment
B39: Health Biological | C39: Blood Bourn Pathogens | D39: Hep B Vaccines provided, Appropriate disposal methods.
C40: Insects/animals | D40: Bites, control
B41: Health Chemical | C41: Industrial Hygiene | D41: Contaminents below occupational exposure limit
...

Sheet Risk Assessment || Step 3 
I1: Completed by: | J1: Name, Position
A2: Date of Assessment Done: | J2: YYYY/MM/DD
A3: Date of Last Update: | J3: YYYY/MM/DD
C4: Step 3: Risk Assessment | L4: Action Planning & After-Risk Rating
J5: Do not paste over | R5: Do not paste over | U5: Do not paste over
C6: Drop-down Field | H6: Drop-down Field | I6: Drop-down Field | J6: Auto-Calc Field | M6: Drop-down Field | O6: Drop-down Field | R6: Auto-Calc Field | S6: Drop-down Field | T6: Drop-down Field | U6: Auto-Calc Field
C7: Area (From S-Matrix) | D7: Job/Activity | E7: Task/Step | F7: Hazard Description | G7: Existing Controls/Defenses | H7: Probability | I7: Severity | J7: Risk Rating | L7: Description of recommended control improvements | M7: Type of Countermeasure | N7: Action Owner: | O7: Capex Required? | P7: Target Completion Date | Q7: Actual Completion Date | R7: Status | S7: Probability | T7: Severity | U7: Risk Rating | V7: Remarks:
J8: {=IFERROR(_xlfn.IFS((AND(H8=10,I8=1)),"L",(AND(H8=10,I8=2)),"H",(AND(H8=10,I8=4)),"VH",(AND(H8=10,I8=6)),"VH",(AND(H8=10,I8=8)),"VH",(AND(H8=10,I8=10)),"VH",(AND(H8=8,I8=1)),"L",(AND(H8=8,I8=2)),"M+",(AND(H8=8,I8=4)),"H",(AND(H8=8,I8=6)),"VH",(AND(H8=8,I8=8)),"VH",(AND(H8=8,I8=10)),"VH",(AND(H8=6,I8=1)),"L",(AND(H8=6,I8=2)),"M",(AND(H8=6,I8=4)),"M+",(AND(H8=6,I8=6)),"H",(AND(H8=6,I8=8)),"VH",(AND(H8=6,I8=10)),"VH",(AND(H8=4,I8=1)),"VL",(AND(H8=4,I8=2)),"L",(AND(H8=4,I8=4)),"M",(AND(H8=4,I8=6)),"M+",(AND(H8=4,I8=8)),"H",(AND(H8=4,I8=10)),"VH",(AND(H8=2,I8=1)),"VL",(AND(H8=2,I8=2)),"VL",(AND(H8=2,I8=4)),"L",(AND(H8=2,I8=6)),"M",(AND(H8=2,I8=8)),"H",(AND(H8=2,I8=10)),"H",(AND(H8=1,I8=1)),"VL",(AND(H8=1,I8=2)),"VL",(AND(H8=1,I8=4)),"L",(AND(H8=1,I8=6)),"L",(AND(H8=1,I8=8)),"M+",(AND(H8=1,I8=10)),"H"),"")} | R8: {=_xlfn.IFS(ISBLANK(L8),"",AND(ISBLANK(Q8),P8<TODAY()),"Over Due",ISBLANK(Q8),"Open",NOT(ISBLANK(Q8)),"Closed")} | U8: {=IFERROR(_xlfn.IFS((AND(S8=10,T8=1)),"L",(AND(S8=10,T8=2)),"H",(AND(S8=10,T8=4)),"VH",(AND(S8=10,T8=6)),"VH",(AND(S8=10,T8=8)),"VH",(AND(S8=10,T8=10)),"VH",(AND(S8=8,T8=1)),"L",(AND(S8=8,T8=2)),"M+",(AND(S8=8,T8=4)),"H",(AND(S8=8,T8=6)),"VH",(AND(S8=8,T8=8)),"VH",(AND(S8=8,T8=10)),"VH",(AND(S8=6,T8=1)),"L",(AND(S8=6,T8=2)),"M",(AND(S8=6,T8=4)),"M+",(AND(S8=6,T8=6)),"H",(AND(S8=6,T8=8)),"VH",(AND(S8=6,T8=10)),"VH",(AND(S8=4,T8=1)),"VL",(AND(S8=4,T8=2)),"L",(AND(S8=4,T8=4)),"M",(AND(S8=4,T8=6)),"M+",(AND(S8=4,T8=8)),"H",(AND(S8=4,T8=10)),"VH",(AND(S8=2,T8=1)),"VL",(AND(S8=2,T8=2)),"VL",(AND(S8=2,T8=4)),"L",(AND(S8=2,T8=6)),"M",(AND(S8=2,T8=8)),"H",(AND(S8=2,T8=10)),"H",(AND(S8=1,T8=1)),"VL",(AND(S8=1,T8=2)),"VL",(AND(S8=1,T8=4)),"L",(AND(S8=1,T8=6)),"L",(AND(S8=1,T8=8)),"M+",(AND(S8=1,T8=10)),"H"),"")}
J9: {=IFERROR(_xlfn.IFS((AND(H9=10,I9=1)),"L",(AND(H9=10,I9=2)),"H",(AND(H9=10,I9=4)),"VH",(AND(H9=10,I9=6)),"VH",(AND(H9=10,I9=8)),"VH",(AND(H9=10,I9=10)),"VH",(AND(H9=8,I9=1)),"L",(AND(H9=8,I9=2)),"M+",(AND(H9=8,I9=4)),"H",(AND(H9=8,I9=6)),"VH",(AND(H9=8,I9=8)),"VH",(AND(H9=8,I9=10)),"VH",(AND(H9=6,I9=1)),"L",(AND(H9=6,I9=2)),"M",(AND(H9=6,I9=4)),"M+",(AND(H9=6,I9=6)),"H",(AND(H9=6,I9=8)),"VH",(AND(H9=6,I9=10)),"VH",(AND(H9=4,I9=1)),"VL",(AND(H9=4,I9=2)),"L",(AND(H9=4,I9=4)),"M",(AND(H9=4,I9=6)),"M+",(AND(H9=4,I9=8)),"H",(AND(H9=4,I9=10)),"VH",(AND(H9=2,I9=1)),"VL",(AND(H9=2,I9=2)),"VL",(AND(H9=2,I9=4)),"L",(AND(H9=2,I9=6)),"M",(AND(H9=2,I9=8)),"H",(AND(H9=2,I9=10)),"H",(AND(H9=1,I9=1)),"VL",(AND(H9=1,I9=2)),"VL",(AND(H9=1,I9=4)),"L",(AND(H9=1,I9=6)),"L",(AND(H9=1,I9=8)),"M+",(AND(H9=1,I9=10)),"H"),"")} | R9: {=_xlfn.IFS(ISBLANK(L9),"",AND(ISBLANK(Q9),P9<TODAY()),"Over Due",ISBLANK(Q9),"Open",NOT(ISBLANK(Q9)),"Closed")} | U9: {=IFERROR(_xlfn.IFS((AND(S9=10,T9=1)),"L",(AND(S9=10,T9=2)),"H",(AND(S9=10,T9=4)),"VH",(AND(S9=10,T9=6)),"VH",(AND(S9=10,T9=8)),"VH",(AND(S9=10,T9=10)),"VH",(AND(S9=8,T9=1)),"L",(AND(S9=8,T9=2)),"M+",(AND(S9=8,T9=4)),"H",(AND(S9=8,T9=6)),"VH",(AND(S9=8,T9=8)),"VH",(AND(S9=8,T9=10)),"VH",(AND(S9=6,T9=1)),"L",(AND(S9=6,T9=2)),"M",(AND(S9=6,T9=4)),"M+",(AND(S9=6,T9=6)),"H",(AND(S9=6,T9=8)),"VH",(AND(S9=6,T9=10)),"VH",(AND(S9=4,T9=1)),"VL",(AND(S9=4,T9=2)),"L",(AND(S9=4,T9=4)),"M",(AND(S9=4,T9=6)),"M+",(AND(S9=4,T9=8)),"H",(AND(S9=4,T9=10)),"VH",(AND(S9=2,T9=1)),"VL",(AND(S9=2,T9=2)),"VL",(AND(S9=2,T9=4)),"L",(AND(S9=2,T9=6)),"M",(AND(S9=2,T9=8)),"H",(AND(S9=2,T9=10)),"H",(AND(S9=1,T9=1)),"VL",(AND(S9=1,T9=2)),"VL",(AND(S9=1,T9=4)),"L",(AND(S9=1,T9=6)),"L",(AND(S9=1,T9=8)),"M+",(AND(S9=1,T9=10)),"H"),"")}
J10: {=IFERROR(_xlfn.IFS((AND(H10=10,I10=1)),"L",(AND(H10=10,I10=2)),"H",(AND(H10=10,I10=4)),"VH",(AND(H10=10,I10=6)),"VH",(AND(H10=10,I10=8)),"VH",(AND(H10=10,I10=10)),"VH",(AND(H10=8,I10=1)),"L",(AND(H10=8,I10=2)),"M+",(AND(H10=8,I10=4)),"H",(AND(H10=8,I10=6)),"VH",(AND(H10=8,I10=8)),"VH",(AND(H10=8,I10=10)),"VH",(AND(H10=6,I10=1)),"L",(AND(H10=6,I10=2)),"M",(AND(H10=6,I10=4)),"M+",(AND(H10=6,I10=6)),"H",(AND(H10=6,I10=8)),"VH",(AND(H10=6,I10=10)),"VH",(AND(H10=4,I10=1)),"VL",(AND(H10=4,I10=2)),"L",(AND(H10=4,I10=4)),"M",(AND(H10=4,I10=6)),"M+",(AND(H10=4,I10=8)),"H",(AND(H10=4,I10=10)),"VH",(AND(H10=2,I10=1)),"VL",(AND(H10=2,I10=2)),"VL",(AND(H10=2,I10=4)),"L",(AND(H10=2,I10=6)),"M",(AND(H10=2,I10=8)),"H",(AND(H10=2,I10=10)),"H",(AND(H10=1,I10=1)),"VL",(AND(H10=1,I10=2)),"VL",(AND(H10=1,I10=4)),"L",(AND(H10=1,I10=6)),"L",(AND(H10=1,I10=8)),"M+",(AND(H10=1,I10=10)),"H"),"")} | R10: {=_xlfn.IFS(ISBLANK(L10),"",AND(ISBLANK(Q10),P10<TODAY()),"Over Due",ISBLANK(Q10),"Open",NOT(ISBLANK(Q10)),"Closed")} | U10: {=IFERROR(_xlfn.IFS((AND(S10=10,T10=1)),"L",(AND(S10=10,T10=2)),"H",(AND(S10=10,T10=4)),"VH",(AND(S10=10,T10=6)),"VH",(AND(S10=10,T10=8)),"VH",(AND(S10=10,T10=10)),"VH",(AND(S10=8,T10=1)),"L",(AND(S10=8,T10=2)),"M+",(AND(S10=8,T10=4)),"H",(AND(S10=8,T10=6)),"VH",(AND(S10=8,T10=8)),"VH",(AND(S10=8,T10=10)),"VH",(AND(S10=6,T10=1)),"L",(AND(S10=6,T10=2)),"M",(AND(S10=6,T10=4)),"M+",(AND(S10=6,T10=6)),"H",(AND(S10=6,T10=8)),"VH",(AND(S10=6,T10=10)),"VH",(AND(S10=4,T10=1)),"VL",(AND(S10=4,T10=2)),"L",(AND(S10=4,T10=4)),"M",(AND(S10=4,T10=6)),"M+",(AND(S10=4,T10=8)),"H",(AND(S10=4,T10=10)),"VH",(AND(S10=2,T10=1)),"VL",(AND(S10=2,T10=2)),"VL",(AND(S10=2,T10=4)),"L",(AND(S10=2,T10=6)),"M",(AND(S10=2,T10=8)),"H",(AND(S10=2,T10=10)),"H",(AND(S10=1,T10=1)),"VL",(AND(S10=1,T10=2)),"VL",(AND(S10=1,T10=4)),"L",(AND(S10=1,T10=6)),"L",(AND(S10=1,T10=8)),"M+",(AND(S10=1,T10=10)),"H"),"")}
J11: {=IFERROR(_xlfn.IFS((AND(H11=10,I11=1)),"L",(AND(H11=10,I11=2)),"H",(AND(H11=10,I11=4)),"VH",(AND(H11=10,I11=6)),"VH",(AND(H11=10,I11=8)),"VH",(AND(H11=10,I11=10)),"VH",(AND(H11=8,I11=1)),"L",(AND(H11=8,I11=2)),"M+",(AND(H11=8,I11=4)),"H",(AND(H11=8,I11=6)),"VH",(AND(H11=8,I11=8)),"VH",(AND(H11=8,I11=10)),"VH",(AND(H11=6,I11=1)),"L",(AND(H11=6,I11=2)),"M",(AND(H11=6,I11=4)),"M+",(AND(H11=6,I11=6)),"H",(AND(H11=6,I11=8)),"VH",(AND(H11=6,I11=10)),"VH",(AND(H11=4,I11=1)),"VL",(AND(H11=4,I11=2)),"L",(AND(H11=4,I11=4)),"M",(AND(H11=4,I11=6)),"M+",(AND(H11=4,I11=8)),"H",(AND(H11=4,I11=10)),"VH",(AND(H11=2,I11=1)),"VL",(AND(H11=2,I11=2)),"VL",(AND(H11=2,I11=4)),"L",(AND(H11=2,I11=6)),"M",(AND(H11=2,I11=8)),"H",(AND(H11=2,I11=10)),"H",(AND(H11=1,I11=1)),"VL",(AND(H11=1,I11=2)),"VL",(AND(H11=1,I11=4)),"L",(AND(H11=1,I11=6)),"L",(AND(H11=1,I11=8)),"M+",(AND(H11=1,I11=10)),"H"),"")} | R11: {=_xlfn.IFS(ISBLANK(L11),"",AND(ISBLANK(Q11),P11<TODAY()),"Over Due",ISBLANK(Q11),"Open",NOT(ISBLANK(Q11)),"Closed")} | U11: {=IFERROR(_xlfn.IFS((AND(S11=10,T11=1)),"L",(AND(S11=10,T11=2)),"H",(AND(S11=10,T11=4)),"VH",(AND(S11=10,T11=6)),"VH",(AND(S11=10,T11=8)),"VH",(AND(S11=10,T11=10)),"VH",(AND(S11=8,T11=1)),"L",(AND(S11=8,T11=2)),"M+",(AND(S11=8,T11=4)),"H",(AND(S11=8,T11=6)),"VH",(AND(S11=8,T11=8)),"VH",(AND(S11=8,T11=10)),"VH",(AND(S11=6,T11=1)),"L",(AND(S11=6,T11=2)),"M",(AND(S11=6,T11=4)),"M+",(AND(S11=6,T11=6)),"H",(AND(S11=6,T11=8)),"VH",(AND(S11=6,T11=10)),"VH",(AND(S11=4,T11=1)),"VL",(AND(S11=4,T11=2)),"L",(AND(S11=4,T11=4)),"M",(AND(S11=4,T11=6)),"M+",(AND(S11=4,T11=8)),"H",(AND(S11=4,T11=10)),"VH",(AND(S11=2,T11=1)),"VL",(AND(S11=2,T11=2)),"VL",(AND(S11=2,T11=4)),"L",(AND(S11=2,T11=6)),"M",(AND(S11=2,T11=8)),"H",(AND(S11=2,T11=10)),"H",(AND(S11=1,T11=1)),"VL",(AND(S11=1,T11=2)),"VL",(AND(S11=1,T11=4)),"L",(AND(S11=1,T11=6)),"L",(AND(S11=1,T11=8)),"M+",(AND(S11=1,T11=10)),"H"),"")}
J12: {=IFERROR(_xlfn.IFS((AND(H12=10,I12=1)),"L",(AND(H12=10,I12=2)),"H",(AND(H12=10,I12=4)),"VH",(AND(H12=10,I12=6)),"VH",(AND(H12=10,I12=8)),"VH",(AND(H12=10,I12=10)),"VH",(AND(H12=8,I12=1)),"L",(AND(H12=8,I12=2)),"M+",(AND(H12=8,I12=4)),"H",(AND(H12=8,I12=6)),"VH",(AND(H12=8,I12=8)),"VH",(AND(H12=8,I12=10)),"VH",(AND(H12=6,I12=1)),"L",(AND(H12=6,I12=2)),"M",(AND(H12=6,I12=4)),"M+",(AND(H12=6,I12=6)),"H",(AND(H12=6,I12=8)),"VH",(AND(H12=6,I12=10)),"VH",(AND(H12=4,I12=1)),"VL",(AND(H12=4,I12=2)),"L",(AND(H12=4,I12=4)),"M",(AND(H12=4,I12=6)),"M+",(AND(H12=4,I12=8)),"H",(AND(H12=4,I12=10)),"VH",(AND(H12=2,I12=1)),"VL",(AND(H12=2,I12=2)),"VL",(AND(H12=2,I12=4)),"L",(AND(H12=2,I12=6)),"M",(AND(H12=2,I12=8)),"H",(AND(H12=2,I12=10)),"H",(AND(H12=1,I12=1)),"VL",(AND(H12=1,I12=2)),"VL",(AND(H12=1,I12=4)),"L",(AND(H12=1,I12=6)),"L",(AND(H12=1,I12=8)),"M+",(AND(H12=1,I12=10)),"H"),"")} | R12: {=_xlfn.IFS(ISBLANK(L12),"",AND(ISBLANK(Q12),P12<TODAY()),"Over Due",ISBLANK(Q12),"Open",NOT(ISBLANK(Q12)),"Closed")} | U12: {=IFERROR(_xlfn.IFS((AND(S12=10,T12=1)),"L",(AND(S12=10,T12=2)),"H",(AND(S12=10,T12=4)),"VH",(AND(S12=10,T12=6)),"VH",(AND(S12=10,T12=8)),"VH",(AND(S12=10,T12=10)),"VH",(AND(S12=8,T12=1)),"L",(AND(S12=8,T12=2)),"M+",(AND(S12=8,T12=4)),"H",(AND(S12=8,T12=6)),"VH",(AND(S12=8,T12=8)),"VH",(AND(S12=8,T12=10)),"VH",(AND(S12=6,T12=1)),"L",(AND(S12=6,T12=2)),"M",(AND(S12=6,T12=4)),"M+",(AND(S12=6,T12=6)),"H",(AND(S12=6,T12=8)),"VH",(AND(S12=6,T12=10)),"VH",(AND(S12=4,T12=1)),"VL",(AND(S12=4,T12=2)),"L",(AND(S12=4,T12=4)),"M",(AND(S12=4,T12=6)),"M+",(AND(S12=4,T12=8)),"H",(AND(S12=4,T12=10)),"VH",(AND(S12=2,T12=1)),"VL",(AND(S12=2,T12=2)),"VL",(AND(S12=2,T12=4)),"L",(AND(S12=2,T12=6)),"M",(AND(S12=2,T12=8)),"H",(AND(S12=2,T12=10)),"H",(AND(S12=1,T12=1)),"VL",(AND(S12=1,T12=2)),"VL",(AND(S12=1,T12=4)),"L",(AND(S12=1,T12=6)),"L",(AND(S12=1,T12=8)),"M+",(AND(S12=1,T12=10)),"H"),"")}
J13: {=IFERROR(_xlfn.IFS((AND(H13=10,I13=1)),"L",(AND(H13=10,I13=2)),"H",(AND(H13=10,I13=4)),"VH",(AND(H13=10,I13=6)),"VH",(AND(H13=10,I13=8)),"VH",(AND(H13=10,I13=10)),"VH",(AND(H13=8,I13=1)),"L",(AND(H13=8,I13=2)),"M+",(AND(H13=8,I13=4)),"H",(AND(H13=8,I13=6)),"VH",(AND(H13=8,I13=8)),"VH",(AND(H13=8,I13=10)),"VH",(AND(H13=6,I13=1)),"L",(AND(H13=6,I13=2)),"M",(AND(H13=6,I13=4)),"M+",(AND(H13=6,I13=6)),"H",(AND(H13=6,I13=8)),"VH",(AND(H13=6,I13=10)),"VH",(AND(H13=4,I13=1)),"VL",(AND(H13=4,I13=2)),"L",(AND(H13=4,I13=4)),"M",(AND(H13=4,I13=6)),"M+",(AND(H13=4,I13=8)),"H",(AND(H13=4,I13=10)),"VH",(AND(H13=2,I13=1)),"VL",(AND(H13=2,I13=2)),"VL",(AND(H13=2,I13=4)),"L",(AND(H13=2,I13=6)),"M",(AND(H13=2,I13=8)),"H",(AND(H13=2,I13=10)),"H",(AND(H13=1,I13=1)),"VL",(AND(H13=1,I13=2)),"VL",(AND(H13=1,I13=4)),"L",(AND(H13=1,I13=6)),"L",(AND(H13=1,I13=8)),"M+",(AND(H13=1,I13=10)),"H"),"")} | R13: {=_xlfn.IFS(ISBLANK(L13),"",AND(ISBLANK(Q13),P13<TODAY()),"Over Due",ISBLANK(Q13),"Open",NOT(ISBLANK(Q13)),"Closed")} | U13: {=IFERROR(_xlfn.IFS((AND(S13=10,T13=1)),"L",(AND(S13=10,T13=2)),"H",(AND(S13=10,T13=4)),"VH",(AND(S13=10,T13=6)),"VH",(AND(S13=10,T13=8)),"VH",(AND(S13=10,T13=10)),"VH",(AND(S13=8,T13=1)),"L",(AND(S13=8,T13=2)),"M+",(AND(S13=8,T13=4)),"H",(AND(S13=8,T13=6)),"VH",(AND(S13=8,T13=8)),"VH",(AND(S13=8,T13=10)),"VH",(AND(S13=6,T13=1)),"L",(AND(S13=6,T13=2)),"M",(AND(S13=6,T13=4)),"M+",(AND(S13=6,T13=6)),"H",(AND(S13=6,T13=8)),"VH",(AND(S13=6,T13=10)),"VH",(AND(S13=4,T13=1)),"VL",(AND(S13=4,T13=2)),"L",(AND(S13=4,T13=4)),"M",(AND(S13=4,T13=6)),"M+",(AND(S13=4,T13=8)),"H",(AND(S13=4,T13=10)),"VH",(AND(S13=2,T13=1)),"VL",(AND(S13=2,T13=2)),"VL",(AND(S13=2,T13=4)),"L",(AND(S13=2,T13=6)),"M",(AND(S13=2,T13=8)),"H",(AND(S13=2,T13=10)),"H",(AND(S13=1,T13=1)),"VL",(AND(S13=1,T13=2)),"VL",(AND(S13=1,T13=4)),"L",(AND(S13=1,T13=6)),"L",(AND(S13=1,T13=8)),"M+",(AND(S13=1,T13=10)),"H"),"")}
J14: {=IFERROR(_xlfn.IFS((AND(H14=10,I14=1)),"L",(AND(H14=10,I14=2)),"H",(AND(H14=10,I14=4)),"VH",(AND(H14=10,I14=6)),"VH",(AND(H14=10,I14=8)),"VH",(AND(H14=10,I14=10)),"VH",(AND(H14=8,I14=1)),"L",(AND(H14=8,I14=2)),"M+",(AND(H14=8,I14=4)),"H",(AND(H14=8,I14=6)),"VH",(AND(H14=8,I14=8)),"VH",(AND(H14=8,I14=10)),"VH",(AND(H14=6,I14=1)),"L",(AND(H14=6,I14=2)),"M",(AND(H14=6,I14=4)),"M+",(AND(H14=6,I14=6)),"H",(AND(H14=6,I14=8)),"VH",(AND(H14=6,I14=10)),"VH",(AND(H14=4,I14=1)),"VL",(AND(H14=4,I14=2)),"L",(AND(H14=4,I14=4)),"M",(AND(H14=4,I14=6)),"M+",(AND(H14=4,I14=8)),"H",(AND(H14=4,I14=10)),"VH",(AND(H14=2,I14=1)),"VL",(AND(H14=2,I14=2)),"VL",(AND(H14=2,I14=4)),"L",(AND(H14=2,I14=6)),"M",(AND(H14=2,I14=8)),"H",(AND(H14=2,I14=10)),"H",(AND(H14=1,I14=1)),"VL",(AND(H14=1,I14=2)),"VL",(AND(H14=1,I14=4)),"L",(AND(H14=1,I14=6)),"L",(AND(H14=1,I14=8)),"M+",(AND(H14=1,I14=10)),"H"),"")} | R14: {=_xlfn.IFS(ISBLANK(L14),"",AND(ISBLANK(Q14),P14<TODAY()),"Over Due",ISBLANK(Q14),"Open",NOT(ISBLANK(Q14)),"Closed")} | U14: {=IFERROR(_xlfn.IFS((AND(S14=10,T14=1)),"L",(AND(S14=10,T14=2)),"H",(AND(S14=10,T14=4)),"VH",(AND(S14=10,T14=6)),"VH",(AND(S14=10,T14=8)),"VH",(AND(S14=10,T14=10)),"VH",(AND(S14=8,T14=1)),"L",(AND(S14=8,T14=2)),"M+",(AND(S14=8,T14=4)),"H",(AND(S14=8,T14=6)),"VH",(AND(S14=8,T14=8)),"VH",(AND(S14=8,T14=10)),"VH",(AND(S14=6,T14=1)),"L",(AND(S14=6,T14=2)),"M",(AND(S14=6,T14=4)),"M+",(AND(S14=6,T14=6)),"H",(AND(S14=6,T14=8)),"VH",(AND(S14=6,T14=10)),"VH",(AND(S14=4,T14=1)),"VL",(AND(S14=4,T14=2)),"L",(AND(S14=4,T14=4)),"M",(AND(S14=4,T14=6)),"M+",(AND(S14=4,T14=8)),"H",(AND(S14=4,T14=10)),"VH",(AND(S14=2,T14=1)),"VL",(AND(S14=2,T14=2)),"VL",(AND(S14=2,T14=4)),"L",(AND(S14=2,T14=6)),"M",(AND(S14=2,T14=8)),"H",(AND(S14=2,T14=10)),"H",(AND(S14=1,T14=1)),"VL",(AND(S14=1,T14=2)),"VL",(AND(S14=1,T14=4)),"L",(AND(S14=1,T14=6)),"L",(AND(S14=1,T14=8)),"M+",(AND(S14=1,T14=10)),"H"),"")}
J15: {=IFERROR(_xlfn.IFS((AND(H15=10,I15=1)),"L",(AND(H15=10,I15=2)),"H",(AND(H15=10,I15=4)),"VH",(AND(H15=10,I15=6)),"VH",(AND(H15=10,I15=8)),"VH",(AND(H15=10,I15=10)),"VH",(AND(H15=8,I15=1)),"L",(AND(H15=8,I15=2)),"M+",(AND(H15=8,I15=4)),"H",(AND(H15=8,I15=6)),"VH",(AND(H15=8,I15=8)),"VH",(AND(H15=8,I15=10)),"VH",(AND(H15=6,I15=1)),"L",(AND(H15=6,I15=2)),"M",(AND(H15=6,I15=4)),"M+",(AND(H15=6,I15=6)),"H",(AND(H15=6,I15=8)),"VH",(AND(H15=6,I15=10)),"VH",(AND(H15=4,I15=1)),"VL",(AND(H15=4,I15=2)),"L",(AND(H15=4,I15=4)),"M",(AND(H15=4,I15=6)),"M+",(AND(H15=4,I15=8)),"H",(AND(H15=4,I15=10)),"VH",(AND(H15=2,I15=1)),"VL",(AND(H15=2,I15=2)),"VL",(AND(H15=2,I15=4)),"L",(AND(H15=2,I15=6)),"M",(AND(H15=2,I15=8)),"H",(AND(H15=2,I15=10)),"H",(AND(H15=1,I15=1)),"VL",(AND(H15=1,I15=2)),"VL",(AND(H15=1,I15=4)),"L",(AND(H15=1,I15=6)),"L",(AND(H15=1,I15=8)),"M+",(AND(H15=1,I15=10)),"H"),"")} | R15: {=_xlfn.IFS(ISBLANK(L15),"",AND(ISBLANK(Q15),P15<TODAY()),"Over Due",ISBLANK(Q15),"Open",NOT(ISBLANK(Q15)),"Closed")} | U15: {=IFERROR(_xlfn.IFS((AND(S15=10,T15=1)),"L",(AND(S15=10,T15=2)),"H",(AND(S15=10,T15=4)),"VH",(AND(S15=10,T15=6)),"VH",(AND(S15=10,T15=8)),"VH",(AND(S15=10,T15=10)),"VH",(AND(S15=8,T15=1)),"L",(AND(S15=8,T15=2)),"M+",(AND(S15=8,T15=4)),"H",(AND(S15=8,T15=6)),"VH",(AND(S15=8,T15=8)),"VH",(AND(S15=8,T15=10)),"VH",(AND(S15=6,T15=1)),"L",(AND(S15=6,T15=2)),"M",(AND(S15=6,T15=4)),"M+",(AND(S15=6,T15=6)),"H",(AND(S15=6,T15=8)),"VH",(AND(S15=6,T15=10)),"VH",(AND(S15=4,T15=1)),"VL",(AND(S15=4,T15=2)),"L",(AND(S15=4,T15=4)),"M",(AND(S15=4,T15=6)),"M+",(AND(S15=4,T15=8)),"H",(AND(S15=4,T15=10)),"VH",(AND(S15=2,T15=1)),"VL",(AND(S15=2,T15=2)),"VL",(AND(S15=2,T15=4)),"L",(AND(S15=2,T15=6)),"M",(AND(S15=2,T15=8)),"H",(AND(S15=2,T15=10)),"H",(AND(S15=1,T15=1)),"VL",(AND(S15=1,T15=2)),"VL",(AND(S15=1,T15=4)),"L",(AND(S15=1,T15=6)),"L",(AND(S15=1,T15=8)),"M+",(AND(S15=1,T15=10)),"H"),"")}
J16: {=IFERROR(_xlfn.IFS((AND(H16=10,I16=1)),"L",(AND(H16=10,I16=2)),"H",(AND(H16=10,I16=4)),"VH",(AND(H16=10,I16=6)),"VH",(AND(H16=10,I16=8)),"VH",(AND(H16=10,I16=10)),"VH",(AND(H16=8,I16=1)),"L",(AND(H16=8,I16=2)),"M+",(AND(H16=8,I16=4)),"H",(AND(H16=8,I16=6)),"VH",(AND(H16=8,I16=8)),"VH",(AND(H16=8,I16=10)),"VH",(AND(H16=6,I16=1)),"L",(AND(H16=6,I16=2)),"M",(AND(H16=6,I16=4)),"M+",(AND(H16=6,I16=6)),"H",(AND(H16=6,I16=8)),"VH",(AND(H16=6,I16=10)),"VH",(AND(H16=4,I16=1)),"VL",(AND(H16=4,I16=2)),"L",(AND(H16=4,I16=4)),"M",(AND(H16=4,I16=6)),"M+",(AND(H16=4,I16=8)),"H",(AND(H16=4,I16=10)),"VH",(AND(H16=2,I16=1)),"VL",(AND(H16=2,I16=2)),"VL",(AND(H16=2,I16=4)),"L",(AND(H16=2,I16=6)),"M",(AND(H16=2,I16=8)),"H",(AND(H16=2,I16=10)),"H",(AND(H16=1,I16=1)),"VL",(AND(H16=1,I16=2)),"VL",(AND(H16=1,I16=4)),"L",(AND(H16=1,I16=6)),"L",(AND(H16=1,I16=8)),"M+",(AND(H16=1,I16=10)),"H"),"")} | R16: {=_xlfn.IFS(ISBLANK(L16),"",AND(ISBLANK(Q16),P16<TODAY()),"Over Due",ISBLANK(Q16),"Open",NOT(ISBLANK(Q16)),"Closed")} | U16: {=IFERROR(_xlfn.IFS((AND(S16=10,T16=1)),"L",(AND(S16=10,T16=2)),"H",(AND(S16=10,T16=4)),"VH",(AND(S16=10,T16=6)),"VH",(AND(S16=10,T16=8)),"VH",(AND(S16=10,T16=10)),"VH",(AND(S16=8,T16=1)),"L",(AND(S16=8,T16=2)),"M+",(AND(S16=8,T16=4)),"H",(AND(S16=8,T16=6)),"VH",(AND(S16=8,T16=8)),"VH",(AND(S16=8,T16=10)),"VH",(AND(S16=6,T16=1)),"L",(AND(S16=6,T16=2)),"M",(AND(S16=6,T16=4)),"M+",(AND(S16=6,T16=6)),"H",(AND(S16=6,T16=8)),"VH",(AND(S16=6,T16=10)),"VH",(AND(S16=4,T16=1)),"VL",(AND(S16=4,T16=2)),"L",(AND(S16=4,T16=4)),"M",(AND(S16=4,T16=6)),"M+",(AND(S16=4,T16=8)),"H",(AND(S16=4,T16=10)),"VH",(AND(S16=2,T16=1)),"VL",(AND(S16=2,T16=2)),"VL",(AND(S16=2,T16=4)),"L",(AND(S16=2,T16=6)),"M",(AND(S16=2,T16=8)),"H",(AND(S16=2,T16=10)),"H",(AND(S16=1,T16=1)),"VL",(AND(S16=1,T16=2)),"VL",(AND(S16=1,T16=4)),"L",(AND(S16=1,T16=6)),"L",(AND(S16=1,T16=8)),"M+",(AND(S16=1,T16=10)),"H"),"")}
J17: {=IFERROR(_xlfn.IFS((AND(H17=10,I17=1)),"L",(AND(H17=10,I17=2)),"H",(AND(H17=10,I17=4)),"VH",(AND(H17=10,I17=6)),"VH",(AND(H17=10,I17=8)),"VH",(AND(H17=10,I17=10)),"VH",(AND(H17=8,I17=1)),"L",(AND(H17=8,I17=2)),"M+",(AND(H17=8,I17=4)),"H",(AND(H17=8,I17=6)),"VH",(AND(H17=8,I17=8)),"VH",(AND(H17=8,I17=10)),"VH",(AND(H17=6,I17=1)),"L",(AND(H17=6,I17=2)),"M",(AND(H17=6,I17=4)),"M+",(AND(H17=6,I17=6)),"H",(AND(H17=6,I17=8)),"VH",(AND(H17=6,I17=10)),"VH",(AND(H17=4,I17=1)),"VL",(AND(H17=4,I17=2)),"L",(AND(H17=4,I17=4)),"M",(AND(H17=4,I17=6)),"M+",(AND(H17=4,I17=8)),"H",(AND(H17=4,I17=10)),"VH",(AND(H17=2,I17=1)),"VL",(AND(H17=2,I17=2)),"VL",(AND(H17=2,I17=4)),"L",(AND(H17=2,I17=6)),"M",(AND(H17=2,I17=8)),"H",(AND(H17=2,I17=10)),"H",(AND(H17=1,I17=1)),"VL",(AND(H17=1,I17=2)),"VL",(AND(H17=1,I17=4)),"L",(AND(H17=1,I17=6)),"L",(AND(H17=1,I17=8)),"M+",(AND(H17=1,I17=10)),"H"),"")} | R17: {=_xlfn.IFS(ISBLANK(L17),"",AND(ISBLANK(Q17),P17<TODAY()),"Over Due",ISBLANK(Q17),"Open",NOT(ISBLANK(Q17)),"Closed")} | U17: {=IFERROR(_xlfn.IFS((AND(S17=10,T17=1)),"L",(AND(S17=10,T17=2)),"H",(AND(S17=10,T17=4)),"VH",(AND(S17=10,T17=6)),"VH",(AND(S17=10,T17=8)),"VH",(AND(S17=10,T17=10)),"VH",(AND(S17=8,T17=1)),"L",(AND(S17=8,T17=2)),"M+",(AND(S17=8,T17=4)),"H",(AND(S17=8,T17=6)),"VH",(AND(S17=8,T17=8)),"VH",(AND(S17=8,T17=10)),"VH",(AND(S17=6,T17=1)),"L",(AND(S17=6,T17=2)),"M",(AND(S17=6,T17=4)),"M+",(AND(S17=6,T17=6)),"H",(AND(S17=6,T17=8)),"VH",(AND(S17=6,T17=10)),"VH",(AND(S17=4,T17=1)),"VL",(AND(S17=4,T17=2)),"L",(AND(S17=4,T17=4)),"M",(AND(S17=4,T17=6)),"M+",(AND(S17=4,T17=8)),"H",(AND(S17=4,T17=10)),"VH",(AND(S17=2,T17=1)),"VL",(AND(S17=2,T17=2)),"VL",(AND(S17=2,T17=4)),"L",(AND(S17=2,T17=6)),"M",(AND(S17=2,T17=8)),"H",(AND(S17=2,T17=10)),"H",(AND(S17=1,T17=1)),"VL",(AND(S17=1,T17=2)),"VL",(AND(S17=1,T17=4)),"L",(AND(S17=1,T17=6)),"L",(AND(S17=1,T17=8)),"M+",(AND(S17=1,T17=10)),"H"),"")}
J18: {=IFERROR(_xlfn.IFS((AND(H18=10,I18=1)),"L",(AND(H18=10,I18=2)),"H",(AND(H18=10,I18=4)),"VH",(AND(H18=10,I18=6)),"VH",(AND(H18=10,I18=8)),"VH",(AND(H18=10,I18=10)),"VH",(AND(H18=8,I18=1)),"L",(AND(H18=8,I18=2)),"M+",(AND(H18=8,I18=4)),"H",(AND(H18=8,I18=6)),"VH",(AND(H18=8,I18=8)),"VH",(AND(H18=8,I18=10)),"VH",(AND(H18=6,I18=1)),"L",(AND(H18=6,I18=2)),"M",(AND(H18=6,I18=4)),"M+",(AND(H18=6,I18=6)),"H",(AND(H18=6,I18=8)),"VH",(AND(H18=6,I18=10)),"VH",(AND(H18=4,I18=1)),"VL",(AND(H18=4,I18=2)),"L",(AND(H18=4,I18=4)),"M",(AND(H18=4,I18=6)),"M+",(AND(H18=4,I18=8)),"H",(AND(H18=4,I18=10)),"VH",(AND(H18=2,I18=1)),"VL",(AND(H18=2,I18=2)),"VL",(AND(H18=2,I18=4)),"L",(AND(H18=2,I18=6)),"M",(AND(H18=2,I18=8)),"H",(AND(H18=2,I18=10)),"H",(AND(H18=1,I18=1)),"VL",(AND(H18=1,I18=2)),"VL",(AND(H18=1,I18=4)),"L",(AND(H18=1,I18=6)),"L",(AND(H18=1,I18=8)),"M+",(AND(H18=1,I18=10)),"H"),"")} | R18: {=_xlfn.IFS(ISBLANK(L18),"",AND(ISBLANK(Q18),P18<TODAY()),"Over Due",ISBLANK(Q18),"Open",NOT(ISBLANK(Q18)),"Closed")} | U18: {=IFERROR(_xlfn.IFS((AND(S18=10,T18=1)),"L",(AND(S18=10,T18=2)),"H",(AND(S18=10,T18=4)),"VH",(AND(S18=10,T18=6)),"VH",(AND(S18=10,T18=8)),"VH",(AND(S18=10,T18=10)),"VH",(AND(S18=8,T18=1)),"L",(AND(S18=8,T18=2)),"M+",(AND(S18=8,T18=4)),"H",(AND(S18=8,T18=6)),"VH",(AND(S18=8,T18=8)),"VH",(AND(S18=8,T18=10)),"VH",(AND(S18=6,T18=1)),"L",(AND(S18=6,T18=2)),"M",(AND(S18=6,T18=4)),"M+",(AND(S18=6,T18=6)),"H",(AND(S18=6,T18=8)),"VH",(AND(S18=6,T18=10)),"VH",(AND(S18=4,T18=1)),"VL",(AND(S18=4,T18=2)),"L",(AND(S18=4,T18=4)),"M",(AND(S18=4,T18=6)),"M+",(AND(S18=4,T18=8)),"H",(AND(S18=4,T18=10)),"VH",(AND(S18=2,T18=1)),"VL",(AND(S18=2,T18=2)),"VL",(AND(S18=2,T18=4)),"L",(AND(S18=2,T18=6)),"M",(AND(S18=2,T18=8)),"H",(AND(S18=2,T18=10)),"H",(AND(S18=1,T18=1)),"VL",(AND(S18=1,T18=2)),"VL",(AND(S18=1,T18=4)),"L",(AND(S18=1,T18=6)),"L",(AND(S18=1,T18=8)),"M+",(AND(S18=1,T18=10)),"H"),"")}
J19: {=IFERROR(_xlfn.IFS((AND(H19=10,I19=1)),"L",(AND(H19=10,I19=2)),"H",(AND(H19=10,I19=4)),"VH",(AND(H19=10,I19=6)),"VH",(AND(H19=10,I19=8)),"VH",(AND(H19=10,I19=10)),"VH",(AND(H19=8,I19=1)),"L",(AND(H19=8,I19=2)),"M+",(AND(H19=8,I19=4)),"H",(AND(H19=8,I19=6)),"VH",(AND(H19=8,I19=8)),"VH",(AND(H19=8,I19=10)),"VH",(AND(H19=6,I19=1)),"L",(AND(H19=6,I19=2)),"M",(AND(H19=6,I19=4)),"M+",(AND(H19=6,I19=6)),"H",(AND(H19=6,I19=8)),"VH",(AND(H19=6,I19=10)),"VH",(AND(H19=4,I19=1)),"VL",(AND(H19=4,I19=2)),"L",(AND(H19=4,I19=4)),"M",(AND(H19=4,I19=6)),"M+",(AND(H19=4,I19=8)),"H",(AND(H19=4,I19=10)),"VH",(AND(H19=2,I19=1)),"VL",(AND(H19=2,I19=2)),"VL",(AND(H19=2,I19=4)),"L",(AND(H19=2,I19=6)),"M",(AND(H19=2,I19=8)),"H",(AND(H19=2,I19=10)),"H",(AND(H19=1,I19=1)),"VL",(AND(H19=1,I19=2)),"VL",(AND(H19=1,I19=4)),"L",(AND(H19=1,I19=6)),"L",(AND(H19=1,I19=8)),"M+",(AND(H19=1,I19=10)),"H"),"")} | R19: {=_xlfn.IFS(ISBLANK(L19),"",AND(ISBLANK(Q19),P19<TODAY()),"Over Due",ISBLANK(Q19),"Open",NOT(ISBLANK(Q19)),"Closed")} | U19: {=IFERROR(_xlfn.IFS((AND(S19=10,T19=1)),"L",(AND(S19=10,T19=2)),"H",(AND(S19=10,T19=4)),"VH",(AND(S19=10,T19=6)),"VH",(AND(S19=10,T19=8)),"VH",(AND(S19=10,T19=10)),"VH",(AND(S19=8,T19=1)),"L",(AND(S19=8,T19=2)),"M+",(AND(S19=8,T19=4)),"H",(AND(S19=8,T19=6)),"VH",(AND(S19=8,T19=8)),"VH",(AND(S19=8,T19=10)),"VH",(AND(S19=6,T19=1)),"L",(AND(S19=6,T19=2)),"M",(AND(S19=6,T19=4)),"M+",(AND(S19=6,T19=6)),"H",(AND(S19=6,T19=8)),"VH",(AND(S19=6,T19=10)),"VH",(AND(S19=4,T19=1)),"VL",(AND(S19=4,T19=2)),"L",(AND(S19=4,T19=4)),"M",(AND(S19=4,T19=6)),"M+",(AND(S19=4,T19=8)),"H",(AND(S19=4,T19=10)),"VH",(AND(S19=2,T19=1)),"VL",(AND(S19=2,T19=2)),"VL",(AND(S19=2,T19=4)),"L",(AND(S19=2,T19=6)),"M",(AND(S19=2,T19=8)),"H",(AND(S19=2,T19=10)),"H",(AND(S19=1,T19=1)),"VL",(AND(S19=1,T19=2)),"VL",(AND(S19=1,T19=4)),"L",(AND(S19=1,T19=6)),"L",(AND(S19=1,T19=8)),"M+",(AND(S19=1,T19=10)),"H"),"")}
... J231: {=IFERROR(_xlfn.IFS((AND(H231=10,I231=1)),"L",(AND(H231=10,I231=2)),"H",(AND(H231=10,I231=4)),"VH",(AND(H231=10,I231=6)),"VH",(AND(H231=10,I231=8)),"VH",(AND(H231=10,I231=10)),"VH",(AND(H231=8,I231=1)),"L",(AND(H231=8,I231=2)),"M+",(AND(H231=8,I231=4)),"H",(AND(H231=8,I231=6)),"VH",(AND(H231=8,I231=8)),"VH",(AND(H231=8,I231=10)),"VH",(AND(H231=6,I231=1)),"L",(AND(H231=6,I231=2)),"M",(AND(H231=6,I231=4)),"M+",(AND(H231=6,I231=6)),"H",(AND(H231=6,I231=8)),"VH",(AND(H231=6,I231=10)),"VH",(AND(H231=4,I231=1)),"VL",(AND(H231=4,I231=2)),"L",(AND(H231=4,I231=4)),"M",(AND(H231=4,I231=6)),"M+",(AND(H231=4,I231=8)),"H",(AND(H231=4,I231=10)),"VH",(AND(H231=2,I231=1)),"VL",(AND(H231=2,I231=2)),"VL",(AND(H231=2,I231=4)),"L",(AND(H231=2,I231=6)),"M",(AND(H231=2,I231=8)),"H",(AND(H231=2,I231=10)),"H",(AND(H231=1,I231=1)),"VL",(AND(H231=1,I231=2)),"VL",(AND(H231=1,I231=4)),"L",(AND(H231=1,I231=6)),"L",(AND(H231=1,I231=8)),"M+",(AND(H231=1,I231=10)),"H"),"")} | R231: {=_xlfn.IFS(ISBLANK(L231),"",AND(ISBLANK(Q231),P231<TODAY()),"Over Due",ISBLANK(Q231),"Open",NOT(ISBLANK(Q231)),"Closed")} | U231: {=IFERROR(_xlfn.IFS((AND(S231=10,T231=1)),"L",(AND(S231=10,T231=2)),"H",(AND(S231=10,T231=4)),"VH",(AND(S231=10,T231=6)),"VH",(AND(S231=10,T231=8)),"VH",(AND(S231=10,T231=10)),"VH",(AND(S231=8,T231=1)),"L",(AND(S231=8,T231=2)),"M+",(AND(S231=8,T231=4)),"H",(AND(S231=8,T231=6)),"VH",(AND(S231=8,T231=8)),"VH",(AND(S231=8,T231=10)),"VH",(AND(S231=6,T231=1)),"L",(AND(S231=6,T231=2)),"M",(AND(S231=6,T231=4)),"M+",(AND(S231=6,T231=6)),"H",(AND(S231=6,T231=8)),"VH",(AND(S231=6,T231=10)),"VH",(AND(S231=4,T231=1)),"VL",(AND(S231=4,T231=2)),"L",(AND(S231=4,T231=4)),"M",(AND(S231=4,T231=6)),"M+",(AND(S231=4,T231=8)),"H",(AND(S231=4,T231=10)),"VH",(AND(S231=2,T231=1)),"VL",(AND(S231=2,T231=2)),"VL",(AND(S231=2,T231=4)),"L",(AND(S231=2,T231=6)),"M",(AND(S231=2,T231=8)),"H",(AND(S231=2,T231=10)),"H",(AND(S231=1,T231=1)),"VL",(AND(S231=1,T231=2)),"VL",(AND(S231=1,T231=4)),"L",(AND(S231=1,T231=6)),"L",(AND(S231=1,T231=8)),"M+",(AND(S231=1,T231=10)),"H"),"")}
J232: {=IFERROR(_xlfn.IFS((AND(H232=10,I232=1)),"L",(AND(H232=10,I232=2)),"H",(AND(H232=10,I232=4)),"VH",(AND(H232=10,I232=6)),"VH",(AND(H232=10,I232=8)),"VH",(AND(H232=10,I232=10)),"VH",(AND(H232=8,I232=1)),"L",(AND(H232=8,I232=2)),"M+",(AND(H232=8,I232=4)),"H",(AND(H232=8,I232=6)),"VH",(AND(H232=8,I232=8)),"VH",(AND(H232=8,I232=10)),"VH",(AND(H232=6,I232=1)),"L",(AND(H232=6,I232=2)),"M",(AND(H232=6,I232=4)),"M+",(AND(H232=6,I232=6)),"H",(AND(H232=6,I232=8)),"VH",(AND(H232=6,I232=10)),"VH",(AND(H232=4,I232=1)),"VL",(AND(H232=4,I232=2)),"L",(AND(H232=4,I232=4)),"M",(AND(H232=4,I232=6)),"M+",(AND(H232=4,I232=8)),"H",(AND(H232=4,I232=10)),"VH",(AND(H232=2,I232=1)),"VL",(AND(H232=2,I232=2)),"VL",(AND(H232=2,I232=4)),"L",(AND(H232=2,I232=6)),"M",(AND(H232=2,I232=8)),"H",(AND(H232=2,I232=10)),"H",(AND(H232=1,I232=1)),"VL",(AND(H232=1,I232=2)),"VL",(AND(H232=1,I232=4)),"L",(AND(H232=1,I232=6)),"L",(AND(H232=1,I232=8)),"M+",(AND(H232=1,I232=10)),"H"),"")} | U232: {=IFERROR(_xlfn.IFS((AND(S232=10,T232=1)),"L",(AND(S232=10,T232=2)),"H",(AND(S232=10,T232=4)),"VH",(AND(S232=10,T232=6)),"VH",(AND(S232=10,T232=8)),"VH",(AND(S232=10,T232=10)),"VH",(AND(S232=8,T232=1)),"L",(AND(S232=8,T232=2)),"M+",(AND(S232=8,T232=4)),"H",(AND(S232=8,T232=6)),"VH",(AND(S232=8,T232=8)),"VH",(AND(S232=8,T232=10)),"VH",(AND(S232=6,T232=1)),"L",(AND(S232=6,T232=2)),"M",(AND(S232=6,T232=4)),"M+",(AND(S232=6,T232=6)),"H",(AND(S232=6,T232=8)),"VH",(AND(S232=6,T232=10)),"VH",(AND(S232=4,T232=1)),"VL",(AND(S232=4,T232=2)),"L",(AND(S232=4,T232=4)),"M",(AND(S232=4,T232=6)),"M+",(AND(S232=4,T232=8)),"H",(AND(S232=4,T232=10)),"VH",(AND(S232=2,T232=1)),"VL",(AND(S232=2,T232=2)),"VL",(AND(S232=2,T232=4)),"L",(AND(S232=2,T232=6)),"M",(AND(S232=2,T232=8)),"H",(AND(S232=2,T232=10)),"H",(AND(S232=1,T232=1)),"VL",(AND(S232=1,T232=2)),"VL",(AND(S232=1,T232=4)),"L",(AND(S232=1,T232=6)),"L",(AND(S232=1,T232=8)),"M+",(AND(S232=1,T232=10)),"H"),"")}
J233: {=IFERROR(_xlfn.IFS((AND(H233=10,I233=1)),"L",(AND(H233=10,I233=2)),"H",(AND(H233=10,I233=4)),"VH",(AND(H233=10,I233=6)),"VH",(AND(H233=10,I233=8)),"VH",(AND(H233=10,I233=10)),"VH",(AND(H233=8,I233=1)),"L",(AND(H233=8,I233=2)),"M+",(AND(H233=8,I233=4)),"H",(AND(H233=8,I233=6)),"VH",(AND(H233=8,I233=8)),"VH",(AND(H233=8,I233=10)),"VH",(AND(H233=6,I233=1)),"L",(AND(H233=6,I233=2)),"M",(AND(H233=6,I233=4)),"M+",(AND(H233=6,I233=6)),"H",(AND(H233=6,I233=8)),"VH",(AND(H233=6,I233=10)),"VH",(AND(H233=4,I233=1)),"VL",(AND(H233=4,I233=2)),"L",(AND(H233=4,I233=4)),"M",(AND(H233=4,I233=6)),"M+",(AND(H233=4,I233=8)),"H",(AND(H233=4,I233=10)),"VH",(AND(H233=2,I233=1)),"VL",(AND(H233=2,I233=2)),"VL",(AND(H233=2,I233=4)),"L",(AND(H233=2,I233=6)),"M",(AND(H233=2,I233=8)),"H",(AND(H233=2,I233=10)),"H",(AND(H233=1,I233=1)),"VL",(AND(H233=1,I233=2)),"VL",(AND(H233=1,I233=4)),"L",(AND(H233=1,I233=6)),"L",(AND(H233=1,I233=8)),"M+",(AND(H233=1,I233=10)),"H"),"")} | U233: {=IFERROR(_xlfn.IFS((AND(S233=10,T233=1)),"L",(AND(S233=10,T233=2)),"H",(AND(S233=10,T233=4)),"VH",(AND(S233=10,T233=6)),"VH",(AND(S233=10,T233=8)),"VH",(AND(S233=10,T233=10)),"VH",(AND(S233=8,T233=1)),"L",(AND(S233=8,T233=2)),"M+",(AND(S233=8,T233=4)),"H",(AND(S233=8,T233=6)),"VH",(AND(S233=8,T233=8)),"VH",(AND(S233=8,T233=10)),"VH",(AND(S233=6,T233=1)),"L",(AND(S233=6,T233=2)),"M",(AND(S233=6,T233=4)),"M+",(AND(S233=6,T233=6)),"H",(AND(S233=6,T233=8)),"VH",(AND(S233=6,T233=10)),"VH",(AND(S233=4,T233=1)),"VL",(AND(S233=4,T233=2)),"L",(AND(S233=4,T233=4)),"M",(AND(S233=4,T233=6)),"M+",(AND(S233=4,T233=8)),"H",(AND(S233=4,T233=10)),"VH",(AND(S233=2,T233=1)),"VL",(AND(S233=2,T233=2)),"VL",(AND(S233=2,T233=4)),"L",(AND(S233=2,T233=6)),"M",(AND(S233=2,T233=8)),"H",(AND(S233=2,T233=10)),"H",(AND(S233=1,T233=1)),"VL",(AND(S233=1,T233=2)),"VL",(AND(S233=1,T233=4)),"L",(AND(S233=1,T233=6)),"L",(AND(S233=1,T233=8)),"M+",(AND(S233=1,T233=10)),"H"),"")}
J234: {=IFERROR(_xlfn.IFS((AND(H234=10,I234=1)),"L",(AND(H234=10,I234=2)),"H",(AND(H234=10,I234=4)),"VH",(AND(H234=10,I234=6)),"VH",(AND(H234=10,I234=8)),"VH",(AND(H234=10,I234=10)),"VH",(AND(H234=8,I234=1)),"L",(AND(H234=8,I234=2)),"M+",(AND(H234=8,I234=4)),"H",(AND(H234=8,I234=6)),"VH",(AND(H234=8,I234=8)),"VH",(AND(H234=8,I234=10)),"VH",(AND(H234=6,I234=1)),"L",(AND(H234=6,I234=2)),"M",(AND(H234=6,I234=4)),"M+",(AND(H234=6,I234=6)),"H",(AND(H234=6,I234=8)),"VH",(AND(H234=6,I234=10)),"VH",(AND(H234=4,I234=1)),"VL",(AND(H234=4,I234=2)),"L",(AND(H234=4,I234=4)),"M",(AND(H234=4,I234=6)),"M+",(AND(H234=4,I234=8)),"H",(AND(H234=4,I234=10)),"VH",(AND(H234=2,I234=1)),"VL",(AND(H234=2,I234=2)),"VL",(AND(H234=2,I234=4)),"L",(AND(H234=2,I234=6)),"M",(AND(H234=2,I234=8)),"H",(AND(H234=2,I234=10)),"H",(AND(H234=1,I234=1)),"VL",(AND(H234=1,I234=2)),"VL",(AND(H234=1,I234=4)),"L",(AND(H234=1,I234=6)),"L",(AND(H234=1,I234=8)),"M+",(AND(H234=1,I234=10)),"H"),"")} | U234: {=IFERROR(_xlfn.IFS((AND(S234=10,T234=1)),"L",(AND(S234=10,T234=2)),"H",(AND(S234=10,T234=4)),"VH",(AND(S234=10,T234=6)),"VH",(AND(S234=10,T234=8)),"VH",(AND(S234=10,T234=10)),"VH",(AND(S234=8,T234=1)),"L",(AND(S234=8,T234=2)),"M+",(AND(S234=8,T234=4)),"H",(AND(S234=8,T234=6)),"VH",(AND(S234=8,T234=8)),"VH",(AND(S234=8,T234=10)),"VH",(AND(S234=6,T234=1)),"L",(AND(S234=6,T234=2)),"M",(AND(S234=6,T234=4)),"M+",(AND(S234=6,T234=6)),"H",(AND(S234=6,T234=8)),"VH",(AND(S234=6,T234=10)),"VH",(AND(S234=4,T234=1)),"VL",(AND(S234=4,T234=2)),"L",(AND(S234=4,T234=4)),"M",(AND(S234=4,T234=6)),"M+",(AND(S234=4,T234=8)),"H",(AND(S234=4,T234=10)),"VH",(AND(S234=2,T234=1)),"VL",(AND(S234=2,T234=2)),"VL",(AND(S234=2,T234=4)),"L",(AND(S234=2,T234=6)),"M",(AND(S234=2,T234=8)),"H",(AND(S234=2,T234=10)),"H",(AND(S234=1,T234=1)),"VL",(AND(S234=1,T234=2)),"VL",(AND(S234=1,T234=4)),"L",(AND(S234=1,T234=6)),"L",(AND(S234=1,T234=8)),"M+",(AND(S234=1,T234=10)),"H"),"")}
J235: {=IFERROR(_xlfn.IFS((AND(H235=10,I235=1)),"L",(AND(H235=10,I235=2)),"H",(AND(H235=10,I235=4)),"VH",(AND(H235=10,I235=6)),"VH",(AND(H235=10,I235=8)),"VH",(AND(H235=10,I235=10)),"VH",(AND(H235=8,I235=1)),"L",(AND(H235=8,I235=2)),"M+",(AND(H235=8,I235=4)),"H",(AND(H235=8,I235=6)),"VH",(AND(H235=8,I235=8)),"VH",(AND(H235=8,I235=10)),"VH",(AND(H235=6,I235=1)),"L",(AND(H235=6,I235=2)),"M",(AND(H235=6,I235=4)),"M+",(AND(H235=6,I235=6)),"H",(AND(H235=6,I235=8)),"VH",(AND(H235=6,I235=10)),"VH",(AND(H235=4,I235=1)),"VL",(AND(H235=4,I235=2)),"L",(AND(H235=4,I235=4)),"M",(AND(H235=4,I235=6)),"M+",(AND(H235=4,I235=8)),"H",(AND(H235=4,I235=10)),"VH",(AND(H235=2,I235=1)),"VL",(AND(H235=2,I235=2)),"VL",(AND(H235=2,I235=4)),"L",(AND(H235=2,I235=6)),"M",(AND(H235=2,I235=8)),"H",(AND(H235=2,I235=10)),"H",(AND(H235=1,I235=1)),"VL",(AND(H235=1,I235=2)),"VL",(AND(H235=1,I235=4)),"L",(AND(H235=1,I235=6)),"L",(AND(H235=1,I235=8)),"M+",(AND(H235=1,I235=10)),"H"),"")} | U235: {=IFERROR(_xlfn.IFS((AND(S235=10,T235=1)),"L",(AND(S235=10,T235=2)),"H",(AND(S235=10,T235=4)),"VH",(AND(S235=10,T235=6)),"VH",(AND(S235=10,T235=8)),"VH",(AND(S235=10,T235=10)),"VH",(AND(S235=8,T235=1)),"L",(AND(S235=8,T235=2)),"M+",(AND(S235=8,T235=4)),"H",(AND(S235=8,T235=6)),"VH",(AND(S235=8,T235=8)),"VH",(AND(S235=8,T235=10)),"VH",(AND(S235=6,T235=1)),"L",(AND(S235=6,T235=2)),"M",(AND(S235=6,T235=4)),"M+",(AND(S235=6,T235=6)),"H",(AND(S235=6,T235=8)),"VH",(AND(S235=6,T235=10)),"VH",(AND(S235=4,T235=1)),"VL",(AND(S235=4,T235=2)),"L",(AND(S235=4,T235=4)),"M",(AND(S235=4,T235=6)),"M+",(AND(S235=4,T235=8)),"H",(AND(S235=4,T235=10)),"VH",(AND(S235=2,T235=1)),"VL",(AND(S235=2,T235=2)),"VL",(AND(S235=2,T235=4)),"L",(AND(S235=2,T235=6)),"M",(AND(S235=2,T235=8)),"H",(AND(S235=2,T235=10)),"H",(AND(S235=1,T235=1)),"VL",(AND(S235=1,T235=2)),"VL",(AND(S235=1,T235=4)),"L",(AND(S235=1,T235=6)),"L",(AND(S235=1,T235=8)),"M+",(AND(S235=1,T235=10)),"H"),"")}
J236: {=IFERROR(_xlfn.IFS((AND(H236=10,I236=1)),"L",(AND(H236=10,I236=2)),"H",(AND(H236=10,I236=4)),"VH",(AND(H236=10,I236=6)),"VH",(AND(H236=10,I236=8)),"VH",(AND(H236=10,I236=10)),"VH",(AND(H236=8,I236=1)),"L",(AND(H236=8,I236=2)),"M+",(AND(H236=8,I236=4)),"H",(AND(H236=8,I236=6)),"VH",(AND(H236=8,I236=8)),"VH",(AND(H236=8,I236=10)),"VH",(AND(H236=6,I236=1)),"L",(AND(H236=6,I236=2)),"M",(AND(H236=6,I236=4)),"M+",(AND(H236=6,I236=6)),"H",(AND(H236=6,I236=8)),"VH",(AND(H236=6,I236=10)),"VH",(AND(H236=4,I236=1)),"VL",(AND(H236=4,I236=2)),"L",(AND(H236=4,I236=4)),"M",(AND(H236=4,I236=6)),"M+",(AND(H236=4,I236=8)),"H",(AND(H236=4,I236=10)),"VH",(AND(H236=2,I236=1)),"VL",(AND(H236=2,I236=2)),"VL",(AND(H236=2,I236=4)),"L",(AND(H236=2,I236=6)),"M",(AND(H236=2,I236=8)),"H",(AND(H236=2,I236=10)),"H",(AND(H236=1,I236=1)),"VL",(AND(H236=1,I236=2)),"VL",(AND(H236=1,I236=4)),"L",(AND(H236=1,I236=6)),"L",(AND(H236=1,I236=8)),"M+",(AND(H236=1,I236=10)),"H"),"")} | U236: {=IFERROR(_xlfn.IFS((AND(S236=10,T236=1)),"L",(AND(S236=10,T236=2)),"H",(AND(S236=10,T236=4)),"VH",(AND(S236=10,T236=6)),"VH",(AND(S236=10,T236=8)),"VH",(AND(S236=10,T236=10)),"VH",(AND(S236=8,T236=1)),"L",(AND(S236=8,T236=2)),"M+",(AND(S236=8,T236=4)),"H",(AND(S236=8,T236=6)),"VH",(AND(S236=8,T236=8)),"VH",(AND(S236=8,T236=10)),"VH",(AND(S236=6,T236=1)),"L",(AND(S236=6,T236=2)),"M",(AND(S236=6,T236=4)),"M+",(AND(S236=6,T236=6)),"H",(AND(S236=6,T236=8)),"VH",(AND(S236=6,T236=10)),"VH",(AND(S236=4,T236=1)),"VL",(AND(S236=4,T236=2)),"L",(AND(S236=4,T236=4)),"M",(AND(S236=4,T236=6)),"M+",(AND(S236=4,T236=8)),"H",(AND(S236=4,T236=10)),"VH",(AND(S236=2,T236=1)),"VL",(AND(S236=2,T236=2)),"VL",(AND(S236=2,T236=4)),"L",(AND(S236=2,T236=6)),"M",(AND(S236=2,T236=8)),"H",(AND(S236=2,T236=10)),"H",(AND(S236=1,T236=1)),"VL",(AND(S236=1,T236=2)),"VL",(AND(S236=1,T236=4)),"L",(AND(S236=1,T236=6)),"L",(AND(S236=1,T236=8)),"M+",(AND(S236=1,T236=10)),"H"),"")}
